Workbook

Sheet Median MGCs
C2: BHI | D2: MAGVN | E2: RPMI | F2: LB | G2: DMEM | H2: MAP | I2: MAGV | J2: MHB-F | K2: MHB-S | L2: AU | M2: MHB | N2: MAG | O2: MAFr | P2: MAR | Q2: MAGly | R2: MAG-Na | S2: MAG-Tr | T2: MAFu | U2: MA | V2: MAGN | W2: MG
B3: Ciprofloxacin | C3: =MEDIAN('MGCs each plate'!C3:E3) -> 0.018310547 | D3: =MEDIAN('MGCs each plate'!F3:H3) -> 0.012207031 | E3: =MEDIAN('MGCs each plate'!I3:K3) -> 0.0061035156 | F3: =MEDIAN('MGCs each plate'!L3:N3) -> 0.036621094 | G3: =MEDIAN('MGCs each plate'!O3:Q3) -> 0.024414062 | H3: =MEDIAN('MGCs each plate'!R3:T3) -> 0.012207031 | I3: =MEDIAN('MGCs each plate'!U3:W3) -> 0.018310547 | J3: =MEDIAN('MGCs each plate'!X3:Z3) -> 0.0091552734 | K3: =MEDIAN('MGCs each plate'!AA3:AC3) -> 0.0045776367 | L3: =MEDIAN('MGCs each plate'!AD3:AF3) -> 0.0061035156 | M3: =MEDIAN('MGCs each plate'!AG3:AI3) -> 0.012207031 | N3: =MEDIAN('MGCs each plate'!AJ3:AL3) -> 0.018310547 | O3: =MEDIAN('MGCs each plate'!AM3:AO3) -> 0.018310547 | P3: =MEDIAN('MGCs each plate'!AP3:AR3) -> 0.0091552734 | Q3: =MEDIAN('MGCs each plate'!AS3:AU3) -> 0.018310547 | R3: =MEDIAN('MGCs each plate'!AV3:AX3) -> 0.0061035156 | S3: =MEDIAN('MGCs each plate'!AY3:BA3) -> 0.018310547 | T3: =MEDIAN('MGCs each plate'!BB3:BD3) -> 0.0091552734 | U3: =MEDIAN('MGCs each plate'!BE3:BG3) -> 0.0045776367 | V3: =MEDIAN('MGCs each plate'!BH3:BJ3) -> 0.012207031 | W3: =MEDIAN('MGCs each plate'!BK3:BM3) -> 0.0091552734
B4: Norfloxacin | C4: =MEDIAN('MGCs each plate'!C4:E4) -> 0.1953125 | D4: =MEDIAN('MGCs each plate'!F4:H4) -> 0.073242188 | E4: =MEDIAN('MGCs each plate'!I4:K4) -> 0.048828125 | F4: =MEDIAN('MGCs each plate'!L4:N4) -> 0.29296875 | G4: =MEDIAN('MGCs each plate'!O4:Q4) -> 0.1953125 | H4: =MEDIAN('MGCs each plate'!R4:T4) -> 0.09765625 | I4: =MEDIAN('MGCs each plate'!U4:W4) -> 0.09765625 | J4: =MEDIAN('MGCs each plate'!X4:Z4) -> 0.048828125 | K4: =MEDIAN('MGCs each plate'!AA4:AC4) -> 0.036621094 | L4: =MEDIAN('MGCs each plate'!AD4:AF4) -> 0.048828125 | M4: =MEDIAN('MGCs each plate'!AG4:AI4) -> 0.073242188 | N4: =MEDIAN('MGCs each plate'!AJ4:AL4) -> 0.09765625 | O4: =MEDIAN('MGCs each plate'!AM4:AO4) -> 0.09765625 | P4: =MEDIAN('MGCs each plate'!AP4:AR4) -> 0.073242188 | Q4: =MEDIAN('MGCs each plate'!AS4:AU4) -> 0.073242188 | R4: =MEDIAN('MGCs each plate'!AV4:AX4) -> 0.048828125 | S4: =MEDIAN('MGCs each plate'!AY4:BA4) -> 0.09765625 | T4: =MEDIAN('MGCs each plate'!BB4:BD4) -> 0.073242188 | U4: =MEDIAN('MGCs each plate'!BE4:BG4) -> 0.036621094 | V4: =MEDIAN('MGCs each plate'!BH4:BJ4) -> 0.09765625 | W4: =MEDIAN('MGCs each plate'!BK4:BM4) -> 0.048828125
B5: Cefdinir | C5: =MEDIAN('MGCs each plate'!C5:E5) -> 0.390625 | D5: =MEDIAN('MGCs each plate'!F5:H5) -> 0.1953125 | E5: =MEDIAN('MGCs each plate'!I5:K5) -> 0.1953125 | F5: =MEDIAN('MGCs each plate'!L5:N5) -> 0.5859375 | G5: =MEDIAN('MGCs each plate'!O5:Q5) -> 0.390625 | H5: =MEDIAN('MGCs each plate'!R5:T5) -> 0.14648438 | I5: =MEDIAN('MGCs each plate'!U5:W5) -> 0.14648438 | J5: =MEDIAN('MGCs each plate'!X5:Z5) -> 0.1953125 | K5: =MEDIAN('MGCs each plate'!AA5:AC5) -> 0.29296875 | L5: =MEDIAN('MGCs each plate'!AD5:AF5) -> 0.048828125 | M5: =MEDIAN('MGCs each plate'!AG5:AI5) -> 0.390625 | N5: =MEDIAN('MGCs each plate'!AJ5:AL5) -> 0.14648438 | O5: =MEDIAN('MGCs each plate'!AM5:AO5) -> 0.14648438 | P5: =MEDIAN('MGCs each plate'!AP5:AR5) -> 0.073242188 | Q5: =MEDIAN('MGCs each plate'!AS5:AU5) -> 0.073242188 | R5: =MEDIAN('MGCs each plate'!AV5:AX5) -> 0.24414062 | S5: =MEDIAN('MGCs each plate'!AY5:BA5) -> 0.1953125 | T5: =MEDIAN('MGCs each plate'!BB5:BD5) -> 0.073242188 | U5: =MEDIAN('MGCs each plate'!BE5:BG5) -> 0.048828125 | V5: =MEDIAN('MGCs each plate'!BH5:BJ5) -> 0.14648438 | W5: =MEDIAN('MGCs each plate'!BK5:BM5) -> 0.09765625
B6: Aztreonam | C6: =MEDIAN('MGCs each plate'!C6:E6) -> 0.09765625 | D6: =MEDIAN('MGCs each plate'!F6:H6) -> 0.018310547 | E6: =MEDIAN('MGCs each plate'!I6:K6) -> 0.048828125 | F6: =MEDIAN('MGCs each plate'!L6:N6) -> 0.073242188 | G6: =MEDIAN('MGCs each plate'!O6:Q6) -> #VALUE! | H6: =MEDIAN('MGCs each plate'!R6:T6) -> 0.012207031 | I6: =MEDIAN('MGCs each plate'!U6:W6) -> 0.036621094 | J6: =MEDIAN('MGCs each plate'!X6:Z6) -> 0.073242188 | K6: =MEDIAN('MGCs each plate'!AA6:AC6) -> 0.073242188 | L6: =MEDIAN('MGCs each plate'!AD6:AF6) -> 0.0061035156 | M6: =MEDIAN('MGCs each plate'!AG6:AI6) -> 0.09765625 | N6: =MEDIAN('MGCs each plate'!AJ6:AL6) -> 0.036621094 | O6: =MEDIAN('MGCs each plate'!AM6:AO6) -> 0.018310547 | P6: =MEDIAN('MGCs each plate'!AP6:AR6) -> 0.0091552734 | Q6: =MEDIAN('MGCs each plate'!AS6:AU6) -> 0.0091552734 | R6: =MEDIAN('MGCs each plate'!AV6:AX6) -> 0.036621094 | S6: =MEDIAN('MGCs each plate'!AY6:BA6) -> 0.048828125 | T6: =MEDIAN('MGCs each plate'!BB6:BD6) -> 0.0091552734 | U6: =MEDIAN('MGCs each plate'!BE6:BG6) -> 0.0091552734 | V6: =MEDIAN('MGCs each plate'!BH6:BJ6) -> 0.018310547 | W6: =MEDIAN('MGCs each plate'!BK6:BM6) -> 0.012207031
B7: Azithromycin | C7: =MEDIAN('MGCs each plate'!C7:E7) -> 1.4648438 | D7: =MEDIAN('MGCs each plate'!F7:H7) -> 3.90625 | E7: =MEDIAN('MGCs each plate'!I7:K7) -> 0.24414062 | F7: =MEDIAN('MGCs each plate'!L7:N7) -> 15.625 | G7: =MEDIAN('MGCs each plate'!O7:Q7) -> 0.24414062 | H7: =MEDIAN('MGCs each plate'!R7:T7) -> 3.90625 | I7: =MEDIAN('MGCs each plate'!U7:W7) -> 3.90625 | J7: =MEDIAN('MGCs each plate'!X7:Z7) -> 0.73242188 | K7: =MEDIAN('MGCs each plate'!AA7:AC7) -> 0.24414062 | L7: =MEDIAN('MGCs each plate'!AD7:AF7) -> 0.9765625 | M7: =MEDIAN('MGCs each plate'!AG7:AI7) -> 1.4648438 | N7: =MEDIAN('MGCs each plate'!AJ7:AL7) -> 3.90625 | O7: =MEDIAN('MGCs each plate'!AM7:AO7) -> 3.90625 | P7: =MEDIAN('MGCs each plate'!AP7:AR7) -> 3.90625 | Q7: =MEDIAN('MGCs each plate'!AS7:AU7) -> 1.953125 | R7: =MEDIAN('MGCs each plate'!AV7:AX7) -> 0.24414062 | S7: =MEDIAN('MGCs each plate'!AY7:BA7) -> 3.90625 | T7: =MEDIAN('MGCs each plate'!BB7:BD7) -> 2.9296875 | U7: =MEDIAN('MGCs each plate'!BE7:BG7) -> 1.953125 | V7: =MEDIAN('MGCs each plate'!BH7:BJ7) -> 3.90625 | W7: =MEDIAN('MGCs each plate'!BK7:BM7) -> 7.8125
B8: Tetracycline HCl | C8: =MEDIAN('MGCs each plate'!C8:E8) -> 1 | D8: =MEDIAN('MGCs each plate'!F8:H8) -> 0.75 | E8: =MEDIAN('MGCs each plate'!I8:K8) -> 8 | F8: =MEDIAN('MGCs each plate'!L8:N8) -> 1.5 | G8: =MEDIAN('MGCs each plate'!O8:Q8) -> 64 | H8: =MEDIAN('MGCs each plate'!R8:T8) -> 0.75 | I8: =MEDIAN('MGCs each plate'!U8:W8) -> 2 | J8: =MEDIAN('MGCs each plate'!X8:Z8) -> 2 | K8: =MEDIAN('MGCs each plate'!AA8:AC8) -> 0.75 | L8: =MEDIAN('MGCs each plate'!AD8:AF8) -> 2 | M8: =MEDIAN('MGCs each plate'!AG8:AI8) -> 1.5 | N8: =MEDIAN('MGCs each plate'!AJ8:AL8) -> 2 | O8: =MEDIAN('MGCs each plate'!AM8:AO8) -> 1.5 | P8: =MEDIAN('MGCs each plate'!AP8:AR8) -> 0.5 | Q8: =MEDIAN('MGCs each plate'!AS8:AU8) -> 1 | R8: =MEDIAN('MGCs each plate'!AV8:AX8) -> 2 | S8: =MEDIAN('MGCs each plate'!AY8:BA8) -> 2 | T8: =MEDIAN('MGCs each plate'!BB8:BD8) -> 1 | U8: =MEDIAN('MGCs each plate'!BE8:BG8) -> 0.375 | V8: =MEDIAN('MGCs each plate'!BH8:BJ8) -> 1 | W8: =MEDIAN('MGCs each plate'!BK8:BM8) -> 1
B9: Kanamycin | C9: =MEDIAN('MGCs each plate'!C9:E9) -> 5.859375 | D9: =MEDIAN('MGCs each plate'!F9:H9) -> 15.625 | E9: =MEDIAN('MGCs each plate'!I9:K9) -> 0.24414062 | F9: =MEDIAN('MGCs each plate'!L9:N9) -> 7.8125 | G9: =MEDIAN('MGCs each plate'!O9:Q9) -> 1.953125 | H9: =MEDIAN('MGCs each plate'!R9:T9) -> 15.625 | I9: =MEDIAN('MGCs each plate'!U9:W9) -> 7.8125 | J9: =MEDIAN('MGCs each plate'!X9:Z9) -> 0.9765625 | K9: =MEDIAN('MGCs each plate'!AA9:AC9) -> 1.953125 | L9: =MEDIAN('MGCs each plate'!AD9:AF9) -> 0.9765625 | M9: =MEDIAN('MGCs each plate'!AG9:AI9) -> 0.9765625 | N9: =MEDIAN('MGCs each plate'!AJ9:AL9) -> 7.8125 | O9: =MEDIAN('MGCs each plate'!AM9:AO9) -> 5.859375 | P9: =MEDIAN('MGCs each plate'!AP9:AR9) -> 7.8125 | Q9: =MEDIAN('MGCs each plate'!AS9:AU9) -> 5.859375 | R9: =MEDIAN('MGCs each plate'!AV9:AX9) -> 1.953125 | S9: =MEDIAN('MGCs each plate'!AY9:BA9) -> 7.8125 | T9: =MEDIAN('MGCs each plate'!BB9:BD9) -> 5.859375 | U9: =MEDIAN('MGCs each plate'!BE9:BG9) -> 5.859375 | V9: =MEDIAN('MGCs each plate'!BH9:BJ9) -> 15.625 | W9: =MEDIAN('MGCs each plate'!BK9:BM9) -> 1.953125
B10: Trimethoprim | C10: =MEDIAN('MGCs each plate'!C10:E10) -> 0.73242188 | D10: =MEDIAN('MGCs each plate'!F10:H10) -> 0.73242188 | E10: =MEDIAN('MGCs each plate'!I10:K10) -> 0.9765625 | F10: =MEDIAN('MGCs each plate'!L10:N10) -> 0.73242188 | G10: =MEDIAN('MGCs each plate'!O10:Q10) -> 1.953125 | H10: =MEDIAN('MGCs each plate'!R10:T10) -> 1.4648438 | I10: =MEDIAN('MGCs each plate'!U10:W10) -> 1.953125 | J10: =MEDIAN('MGCs each plate'!X10:Z10) -> 0.36621094 | K10: =MEDIAN('MGCs each plate'!AA10:AC10) -> 0.12207031 | L10: =MEDIAN('MGCs each plate'!AD10:AF10) -> 0.9765625 | M10: =MEDIAN('MGCs each plate'!AG10:AI10) -> 0.48828125 | N10: =MEDIAN('MGCs each plate'!AJ10:AL10) -> 1.953125 | O10: =MEDIAN('MGCs each plate'!AM10:AO10) -> 2.9296875 | P10: =MEDIAN('MGCs each plate'!AP10:AR10) -> 0.73242188 | Q10: =MEDIAN('MGCs each plate'!AS10:AU10) -> 1.4648438 | R10: =MEDIAN('MGCs each plate'!AV10:AX10) -> 1.4648438 | S10: =MEDIAN('MGCs each plate'!AY10:BA10) -> 1.4648438 | T10: =MEDIAN('MGCs each plate'!BB10:BD10) -> 1.4648438 | U10: =MEDIAN('MGCs each plate'!BE10:BG10) -> 0.73242188 | V10: =MEDIAN('MGCs each plate'!BH10:BJ10) -> 0.48828125 | W10: =MEDIAN('MGCs each plate'!BK10:BM10) -> 0.9765625
B11: Sulfamethoxazole | C11: 1000 | D11: 1000 | E11: =MEDIAN('MGCs each plate'!I11:K11) -> 125 | F11: =MEDIAN('MGCs each plate'!L11:N11) -> 93.75 | G11: 62.5 | H11: =MEDIAN('MGCs each plate'!R11:T11) -> 35.15625 | I11: =MEDIAN('MGCs each plate'!U11:W11) -> 23.4375 | J11: =MEDIAN('MGCs each plate'!X11:Z11) -> 23.4375 | K11: =MEDIAN('MGCs each plate'!AA11:AC11) -> 23.4375 | L11: =MEDIAN('MGCs each plate'!AD11:AF11) -> 15.625 | M11: =MEDIAN('MGCs each plate'!AG11:AI11) -> 11.71875 | N11: =MEDIAN('MGCs each plate'!AJ11:AL11) -> 5.859375 | O11: =MEDIAN('MGCs each plate'!AM11:AO11) -> 5.859375 | P11: =MEDIAN('MGCs each plate'!AP11:AR11) -> 5.859375 | Q11: =MEDIAN('MGCs each plate'!AS11:AU11) -> 5.859375 | R11: =MEDIAN('MGCs each plate'!AV11:AX11) -> 3.90625 | S11: =MEDIAN('MGCs each plate'!AY11:BA11) -> 3.90625 | T11: =MEDIAN('MGCs each plate'!BB11:BD11) -> 3.90625 | U11: =MEDIAN('MGCs each plate'!BE11:BG11) -> 2.9296875 | V11: =MEDIAN('MGCs each plate'!BH11:BJ11) -> 1.953125 | W11: 0.3035
B12: Colistin | C12: =MEDIAN('MGCs each plate'!C12:E12) -> 0.78125 | D12: =MEDIAN('MGCs each plate'!F12:H12) -> 0.78125 | E12: =MEDIAN('MGCs each plate'!I12:K12) -> 0.78125 | F12: =MEDIAN('MGCs each plate'!L12:N12) -> 0.390625 | G12: =MEDIAN('MGCs each plate'!O12:Q12) -> 0.78125 | H12: =MEDIAN('MGCs each plate'!R12:T12) -> 1.5625 | I12: =MEDIAN('MGCs each plate'!U12:W12) -> 0.78125 | J12: =MEDIAN('MGCs each plate'!X12:Z12) -> 1.5625 | K12: =MEDIAN('MGCs each plate'!AA12:AC12) -> 1.5625 | L12: =MEDIAN('MGCs each plate'!AD12:AF12) -> 0.78125 | M12: =MEDIAN('MGCs each plate'!AG12:AI12) -> 1.5625 | N12: =MEDIAN('MGCs each plate'!AJ12:AL12) -> 0.78125 | O12: =MEDIAN('MGCs each plate'!AM12:AO12) -> 0.78125 | P12: =MEDIAN('MGCs each plate'!AP12:AR12) -> 1.5625 | Q12: =MEDIAN('MGCs each plate'!AS12:AU12) -> 0.78125 | R12: =MEDIAN('MGCs each plate'!AV12:AX12) -> 1.5625 | S12: =MEDIAN('MGCs each plate'!AY12:BA12) -> 0.78125 | T12: =MEDIAN('MGCs each plate'!BB12:BD12) -> 0.78125 | U12: =MEDIAN('MGCs each plate'!BE12:BG12) -> 0.78125 | V12: =MEDIAN('MGCs each plate'!BH12:BJ12) -> 0.78125 | W12: =MEDIAN('MGCs each plate'!BK12:BM12) -> 1.5625
B13: Nitrofurantoin | C13: =MEDIAN('MGCs each plate'!C13:E13) -> 11.71875 | D13: =MEDIAN('MGCs each plate'!F13:H13) -> 15.625 | E13: =MEDIAN('MGCs each plate'!I13:K13) -> 31.25 | F13: =MEDIAN('MGCs each plate'!L13:N13) -> 11.71875 | G13: =MEDIAN('MGCs each plate'!O13:Q13) -> 31.25 | H13: =MEDIAN('MGCs each plate'!R13:T13) -> 15.625 | I13: =MEDIAN('MGCs each plate'!U13:W13) -> 15.625 | J13: =MEDIAN('MGCs each plate'!X13:Z13) -> 15.625 | K13: =MEDIAN('MGCs each plate'!AA13:AC13) -> 15.625 | L13: =MEDIAN('MGCs each plate'!AD13:AF13) -> 15.625 | M13: =MEDIAN('MGCs each plate'!AG13:AI13) -> 15.625 | N13: =MEDIAN('MGCs each plate'!AJ13:AL13) -> 15.625 | O13: =MEDIAN('MGCs each plate'!AM13:AO13) -> 31.25 | P13: =MEDIAN('MGCs each plate'!AP13:AR13) -> 15.625 | Q13: =MEDIAN('MGCs each plate'!AS13:AU13) -> 15.625 | R13: =MEDIAN('MGCs each plate'!AV13:AX13) -> 62.5 | S13: =MEDIAN('MGCs each plate'!AY13:BA13) -> 15.625 | T13: =MEDIAN('MGCs each plate'!BB13:BD13) -> 7.8125 | U13: =MEDIAN('MGCs each plate'!BE13:BG13) -> 5.859375 | V13: =MEDIAN('MGCs each plate'!BH13:BJ13) -> 15.625 | W13: =MEDIAN('MGCs each plate'!BK13:BM13) -> 7.8125
B18: Median of MGCs calculated across each plate as shown in tab 'MGCs each plate'
B21: Some SMX values manually changed to those observed in additional experiments to test values outside of original ranges (BHI, SMX, MA) - see end of PowerPoint
B22: DMEM SMX value changed to reflect bias of taking 48 hours rather than 24 hour measurement
B25: Across all tabs, blacked out values are values removed from consideration due to mistake with experiment execution.

Sheet MGCs each plate
B1: Media | C1: BHI | F1: MAGVN | I1: RPMI | L1: LB | O1: DMEM | R1: MAP | U1: MAGV | X1: MHB-F | AA1: MHB-S | AD1: AU | AG1: MHB | AJ1: MAG | AM1: MAFr | AP1: MAR | AS1: MAGly | AV1: MAG-Na | AY1: MAG-Tr | BB1: MAFu | BE1: MA | BH1: MAGN | BK1: MG
B2: Replicate | C2: 1 | D2: 2 | E2: 3 | F2: 1 | G2: 2 | H2: 3 | I2: 1 | J2: 2 | K2: 3 | L2: 1 | M2: 2 | N2: 3 | O2: 1 | P2: 2 | Q2: 3 | R2: 1 | S2: 2 | T2: 3 | U2: 1 | V2: 2 | W2: 3 | X2: 1 | Y2: 2 | Z2: 3 | AA2: 1 | AB2: 2 | AC2: 3 | AD2: 1 | AE2: 2 | AF2: 3 | AG2: 1 | AH2: 2 | AI2: 3 | AJ2: 1 | AK2: 2 | AL2: 3 | AM2: 1 | AN2: 2 | AO2: 3 | AP2: 1 | AQ2: 2 | AR2: 3 | AS2: 1 | AT2: 2 | AU2: 3 | AV2: 1 | AW2: 2 | AX2: 3 | AY2: 1 | AZ2: 2 | BA2: 3 | BB2: 1 | BC2: 2 | BD2: 3 | BE2: 1 | BF2: 2 | BG2: 3 | BH2: 1 | BI2: 2 | BJ2: 3 | BK2: 1 | BL2: 2 | BM2: 3
B3: Ciprofloxacin | C3: {=IF( MOD('Well calls each plate'!C3,1)=0, INDIRECT("'Plate map key'!"&ADDRESS('Well calls each plate'!C3+5,ROW()+1)), AVERAGE( INDIRECT("'Plate map key'!"&ADDRESS(TRUNC('Well calls each plate'!C3)+5,ROW()+1)), INDIRECT("'Plate map key'!"&ADDRESS(TRUNC('Well calls each plate'!C3)+6,ROW()+1)) ) )} -> 0.018310547 | D3: {=IF( MOD('Well calls each plate'!D3,1)=0, INDIRECT("'Plate map key'!"&ADDRESS('Well calls each plate'!D3+5,ROW()+1)), AVERAGE( INDIRECT("'Plate map key'!"&ADDRESS(TRUNC('Well calls each plate'!D3)+5,ROW()+1)), INDIRECT("'Plate map key'!"&ADDRESS(TRUNC('Well calls each plate'!D3)+6,ROW()+1)) ) )} -> 0.018310547 | E3: {=IF( MOD('Well calls each plate'!E3,1)=0, INDIRECT("'Plate map key'!"&ADDRESS('Well calls each plate'!E3+5,ROW()+1)), AVERAGE( INDIRECT("'Plate map key'!"&ADDRESS(TRUNC('Well calls each plate'!E3)+5,ROW()+1)), INDIRECT("'Plate map key'!"&ADDRESS(TRUNC('Well calls each plate'!E3)+6,ROW()+1)) ) )} -> 0.018310547 | F3: {=IF( MOD('Well calls each plate'!F3,1)=0, INDIRECT("'Plate map key'!"&ADDRESS('Well calls each plate'!F3+5,ROW()+1)), AVERAGE( INDIRECT("'Plate map key'!"&ADDRESS(TRUNC('Well calls each plate'!F3)+5,ROW()+1)), INDIRECT("'Plate map key'!"&ADDRESS(TRUNC('Well calls each plate'!F3)+6,ROW()+1)) ) )} -> 0.018310547 | G3: {=IF( MOD('Well calls each plate'!G3,1)=0, INDIRECT("'Plate map key'!"&ADDRESS('Well calls each plate'!G3+5,ROW()+1)), AVERAGE( INDIRECT("'Plate map key'!"&ADDRESS(TRUNC('Well calls each plate'!G3)+5,ROW()+1)), INDIRECT("'Plate map key'!"&ADDRESS(TRUNC('Well calls each plate'!G3)+6,ROW()+1)) ) )} -> 0.012207031 | H3: {=IF( MOD('Well calls each plate'!H3,1)=0, INDIRECT("'Plate map key'!"&ADDRESS('Well calls each plate'!H3+5,ROW()+1)), AVERAGE( INDIRECT("'Plate map key'!"&ADDRESS(TRUNC('Well calls each plate'!H3)+5,ROW()+1)), INDIRECT("'Plate map key'!"&ADDRESS(TRUNC('Well calls each plate'!H3)+6,ROW()+1)) ) )} -> 0.0091552734 | I3: {=IF( MOD('Well calls each plate'!I3,1)=0, INDIRECT("'Plate map key'!"&ADDRESS('Well calls each plate'!I3+5,ROW()+1)), AVERAGE( INDIRECT("'Plate map key'!"&ADDRESS(TRUNC('Well calls each plate'!I3)+5,ROW()+1)), INDIRECT("'Plate map key'!"&ADDRESS(TRUNC('Well calls each plate'!I3)+6,ROW()+1)) ) )} -> 0.0061035156 | J3: {=IF( MOD('Well calls each plate'!J3,1)=0, INDIRECT("'Plate map key'!"&ADDRESS('Well calls each plate'!J3+5,ROW()+1)), AVERAGE( INDIRECT("'Plate map key'!"&ADDRESS(TRUNC('Well calls each plate'!J3)+5,ROW()+1)), INDIRECT("'Plate map key'!"&ADDRESS(TRUNC('Well calls each plate'!J3)+6,ROW()+1)) ) )} -> 0.0061035156 | ... BM3: {=IF( MOD('Well calls each plate'!BM3,1)=0, INDIRECT("'Plate map key'!"&ADDRESS('Well calls each plate'!BM3+5,ROW()+1)), AVERAGE( INDIRECT("'Plate map key'!"&ADDRESS(TRUNC('Well calls each plate'!BM3)+5,ROW()+1)), INDIRECT("'Plate map key'!"&ADDRESS(TRUNC('Well calls each plate'!BM3)+6,ROW()+1)) ) )} -> 0.0091552734
B4: Norfloxacin | C4: {=IF( MOD('Well calls each plate'!C4,1)=0, INDIRECT("'Plate map key'!"&ADDRESS('Well calls each plate'!C4+5,ROW()+1)), AVERAGE( INDIRECT("'Plate map key'!"&ADDRESS(TRUNC('Well calls each plate'!C4)+5,ROW()+1)), INDIRECT("'Plate map key'!"&ADDRESS(TRUNC('Well calls each plate'!C4)+6,ROW()+1)) ) )} -> 0.1953125 | D4: {=IF( MOD('Well calls each plate'!D4,1)=0, INDIRECT("'Plate map key'!"&ADDRESS('Well calls each plate'!D4+5,ROW()+1)), AVERAGE( INDIRECT("'Plate map key'!"&ADDRESS(TRUNC('Well calls each plate'!D4)+5,ROW()+1)), INDIRECT("'Plate map key'!"&ADDRESS(TRUNC('Well calls each plate'!D4)+6,ROW()+1)) ) )} -> 0.1953125 | E4: {=IF( MOD('Well calls each plate'!E4,1)=0, INDIRECT("'Plate map key'!"&ADDRESS('Well calls each plate'!E4+5,ROW()+1)), AVERAGE( INDIRECT("'Plate map key'!"&ADDRESS(TRUNC('Well calls each plate'!E4)+5,ROW()+1)), INDIRECT("'Plate map key'!"&ADDRESS(TRUNC('Well calls each plate'!E4)+6,ROW()+1)) ) )} -> 0.1953125 | F4: {=IF( MOD('Well calls each plate'!F4,1)=0, INDIRECT("'Plate map key'!"&ADDRESS('Well calls each plate'!F4+5,ROW()+1)), AVERAGE( INDIRECT("'Plate map key'!"&ADDRESS(TRUNC('Well calls each plate'!F4)+5,ROW()+1)), INDIRECT("'Plate map key'!"&ADDRESS(TRUNC('Well calls each plate'!F4)+6,ROW()+1)) ) )} -> 0.073242188 | G4: {=IF( MOD('Well calls each plate'!G4,1)=0, INDIRECT("'Plate map key'!"&ADDRESS('Well calls each plate'!G4+5,ROW()+1)), AVERAGE( INDIRECT("'Plate map key'!"&ADDRESS(TRUNC('Well calls each plate'!G4)+5,ROW()+1)), INDIRECT("'Plate map key'!"&ADDRESS(TRUNC('Well calls each plate'!G4)+6,ROW()+1)) ) )} -> 0.09765625 | H4: {=IF( MOD('Well calls each plate'!H4,1)=0, INDIRECT("'Plate map key'!"&ADDRESS('Well calls each plate'!H4+5,ROW()+1)), AVERAGE( INDIRECT("'Plate map key'!"&ADDRESS(TRUNC('Well calls each plate'!H4)+5,ROW()+1)), INDIRECT("'Plate map key'!"&ADDRESS(TRUNC('Well calls each plate'!H4)+6,ROW()+1)) ) )} -> 0.073242188 | I4: {=IF( MOD('Well calls each plate'!I4,1)=0, INDIRECT("'Plate map key'!"&ADDRESS('Well calls each plate'!I4+5,ROW()+1)), AVERAGE( INDIRECT("'Plate map key'!"&ADDRESS(TRUNC('Well calls each plate'!I4)+5,ROW()+1)), INDIRECT("'Plate map key'!"&ADDRESS(TRUNC('Well calls each plate'!I4)+6,ROW()+1)) ) )} -> 0.048828125 | J4: {=IF( MOD('Well calls each plate'!J4,1)=0, INDIRECT("'Plate map key'!"&ADDRESS('Well calls each plate'!J4+5,ROW()+1)), AVERAGE( INDIRECT("'Plate map key'!"&ADDRESS(TRUNC('Well calls each plate'!J4)+5,ROW()+1)), INDIRECT("'Plate map key'!"&ADDRESS(TRUNC('Well calls each plate'!J4)+6,ROW()+1)) ) )} -> 0.024414062 | ... BM4: {=IF( MOD('Well calls each plate'!BM4,1)=0, INDIRECT("'Plate map key'!"&ADDRESS('Well calls each plate'!BM4+5,ROW()+1)), AVERAGE( INDIRECT("'Plate map key'!"&ADDRESS(TRUNC('Well calls each plate'!BM4)+5,ROW()+1)), INDIRECT("'Plate map key'!"&ADDRESS(TRUNC('Well calls each plate'!BM4)+6,ROW()+1)) ) )} -> 0.048828125
B5: Cefdinir | C5: {=IF( MOD('Well calls each plate'!C5,1)=0, INDIRECT("'Plate map key'!"&ADDRESS('Well calls each plate'!C5+5,ROW()+1)), AVERAGE( INDIRECT("'Plate map key'!"&ADDRESS(TRUNC('Well calls each plate'!C5)+5,ROW()+1)), INDIRECT("'Plate map key'!"&ADDRESS(TRUNC('Well calls each plate'!C5)+6,ROW()+1)) ) )} -> 0.390625 | D5: {=IF( MOD('Well calls each plate'!D5,1)=0, INDIRECT("'Plate map key'!"&ADDRESS('Well calls each plate'!D5+5,ROW()+1)), AVERAGE( INDIRECT("'Plate map key'!"&ADDRESS(TRUNC('Well calls each plate'!D5)+5,ROW()+1)), INDIRECT("'Plate map key'!"&ADDRESS(TRUNC('Well calls each plate'!D5)+6,ROW()+1)) ) )} -> 0.390625 | E5: {=IF( MOD('Well calls each plate'!E5,1)=0, INDIRECT("'Plate map key'!"&ADDRESS('Well calls each plate'!E5+5,ROW()+1)), AVERAGE( INDIRECT("'Plate map key'!"&ADDRESS(TRUNC('Well calls each plate'!E5)+5,ROW()+1)), INDIRECT("'Plate map key'!"&ADDRESS(TRUNC('Well calls each plate'!E5)+6,ROW()+1)) ) )} -> 0.390625 | F5: {=IF( MOD('Well calls each plate'!F5,1)=0, INDIRECT("'Plate map key'!"&ADDRESS('Well calls each plate'!F5+5,ROW()+1)), AVERAGE( INDIRECT("'Plate map key'!"&ADDRESS(TRUNC('Well calls each plate'!F5)+5,ROW()+1)), INDIRECT("'Plate map key'!"&ADDRESS(TRUNC('Well calls each plate'!F5)+6,ROW()+1)) ) )} -> 0.14648438 | G5: {=IF( MOD('Well calls each plate'!G5,1)=0, INDIRECT("'Plate map key'!"&ADDRESS('Well calls each plate'!G5+5,ROW()+1)), AVERAGE( INDIRECT("'Plate map key'!"&ADDRESS(TRUNC('Well calls each plate'!G5)+5,ROW()+1)), INDIRECT("'Plate map key'!"&ADDRESS(TRUNC('Well calls each plate'!G5)+6,ROW()+1)) ) )} -> 0.1953125 | H5: {=IF( MOD('Well calls each plate'!H5,1)=0, INDIRECT("'Plate map key'!"&ADDRESS('Well calls each plate'!H5+5,ROW()+1)), AVERAGE( INDIRECT("'Plate map key'!"&ADDRESS(TRUNC('Well calls each plate'!H5)+5,ROW()+1)), INDIRECT("'Plate map key'!"&ADDRESS(TRUNC('Well calls each plate'!H5)+6,ROW()+1)) ) )} -> 0.1953125 | I5: {=IF( MOD('Well calls each plate'!I5,1)=0, INDIRECT("'Plate map key'!"&ADDRESS('Well calls each plate'!I5+5,ROW()+1)), AVERAGE( INDIRECT("'Plate map key'!"&ADDRESS(TRUNC('Well calls each plate'!I5)+5,ROW()+1)), INDIRECT("'Plate map key'!"&ADDRESS(TRUNC('Well calls each plate'!I5)+6,ROW()+1)) ) )} -> 0.1953125 | J5: {=IF( MOD('Well calls each plate'!J5,1)=0, INDIRECT("'Plate map key'!"&ADDRESS('Well calls each plate'!J5+5,ROW()+1)), AVERAGE( INDIRECT("'Plate map key'!"&ADDRESS(TRUNC('Well calls each plate'!J5)+5,ROW()+1)), INDIRECT("'Plate map key'!"&ADDRESS(TRUNC('Well calls each plate'!J5)+6,ROW()+1)) ) )} -> 0.1953125 | ... AU5: {=IF( MOD('Well calls each plate'!AU5,1)=0, INDIRECT("'Plate map key'!"&ADDRESS('Well calls each plate'!AU5+5,ROW()+1)), AVERAGE( INDIRECT("'Plate map key'!"&ADDRESS(TRUNC('Well calls each plate'!AU5)+5,ROW()+1)), INDIRECT("'Plate map key'!"&ADDRESS(TRUNC('Well calls each plate'!AU5)+6,ROW()+1)) ) )} -> 0.048828125 | AV5: =MEDIAN(AW5:AX5) -> 0.24414062 | AW5: {=IF( MOD('Well calls each plate'!AW5,1)=0, INDIRECT("'Plate map key'!"&ADDRESS('Well calls each plate'!AW5+5,ROW()+1)), AVERAGE( INDIRECT("'Plate map key'!"&ADDRESS(TRUNC('Well calls each plate'!AW5)+5,ROW()+1)), INDIRECT("'Plate map key'!"&ADDRESS(TRUNC('Well calls each plate'!AW5)+6,ROW()+1)) ) )} -> 0.29296875 | AX5: {=IF( MOD('Well calls each plate'!AX5,1)=0, INDIRECT("'Plate map key'!"&ADDRESS('Well calls each plate'!AX5+5,ROW()+1)), AVERAGE( INDIRECT("'Plate map key'!"&ADDRESS(TRUNC('Well calls each plate'!AX5)+5,ROW()+1)), INDIRECT("'Plate map key'!"&ADDRESS(TRUNC('Well calls each plate'!AX5)+6,ROW()+1)) ) )} -> 0.1953125 | AY5: {=IF( MOD('Well calls each plate'!AY5,1)=0, INDIRECT("'Plate map key'!"&ADDRESS('Well calls each plate'!AY5+5,ROW()+1)), AVERAGE( INDIRECT("'Plate map key'!"&ADDRESS(TRUNC('Well calls each plate'!AY5)+5,ROW()+1)), INDIRECT("'Plate map key'!"&ADDRESS(TRUNC('Well calls each plate'!AY5)+6,ROW()+1)) ) )} -> 0.1953125 | AZ5: {=IF( MOD('Well calls each plate'!AZ5,1)=0, INDIRECT("'Plate map key'!"&ADDRESS('Well calls each plate'!AZ5+5,ROW()+1)), AVERAGE( INDIRECT("'Plate map key'!"&ADDRESS(TRUNC('Well calls each plate'!AZ5)+5,ROW()+1)), INDIRECT("'Plate map key'!"&ADDRESS(TRUNC('Well calls each plate'!AZ5)+6,ROW()+1)) ) )} -> 0.1953125 | BA5: {=IF( MOD('Well calls each plate'!BA5,1)=0, INDIRECT("'Plate map key'!"&ADDRESS('Well calls each plate'!BA5+5,ROW()+1)), AVERAGE( INDIRECT("'Plate map key'!"&ADDRESS(TRUNC('Well calls each plate'!BA5)+5,ROW()+1)), INDIRECT("'Plate map key'!"&ADDRESS(TRUNC('Well calls each plate'!BA5)+6,ROW()+1)) ) )} -> 0.1953125 | BB5: {=IF( MOD('Well calls each plate'!BB5,1)=0, INDIRECT("'Plate map key'!"&ADDRESS('Well calls each plate'!BB5+5,ROW()+1)), AVERAGE( INDIRECT("'Plate map key'!"&ADDRESS(TRUNC('Well calls each plate'!BB5)+5,ROW()+1)), INDIRECT("'Plate map key'!"&ADDRESS(TRUNC('Well calls each plate'!BB5)+6,ROW()+1)) ) )} -> 0.073242188 | BC5: {=IF( MOD('Well calls each plate'!BC5,1)=0, INDIRECT("'Plate map key'!"&ADDRESS('Well calls each plate'!BC5+5,ROW()+1)), AVERAGE( INDIRECT("'Plate map key'!"&ADDRESS(TRUNC('Well calls each plate'!BC5)+5,ROW()+1)), INDIRECT("'Plate map key'!"&ADDRESS(TRUNC('Well calls each plate'!BC5)+6,ROW()+1)) ) )} -> 0.073242188 | BD5: {=IF( MOD('Well calls each plate'!BD5,1)=0, INDIRECT("'Plate map key'!"&ADDRESS('Well calls each plate'!BD5+5,ROW()+1)), AVERAGE( INDIRECT("'Plate map key'!"&ADDRESS(TRUNC('Well calls each plate'!BD5)+5,ROW()+1)), INDIRECT("'Plate map key'!"&ADDRESS(TRUNC('Well calls each plate'!BD5)+6,ROW()+1)) ) )} -> 0.048828125 | ... BM5: {=IF( MOD('Well calls each plate'!BM5,1)=0, INDIRECT("'Plate map key'!"&ADDRESS('Well calls each plate'!BM5+5,ROW()+1)), AVERAGE( INDIRECT("'Plate map key'!"&ADDRESS(TRUNC('Well calls each plate'!BM5)+5,ROW()+1)), INDIRECT("'Plate map key'!"&ADDRESS(TRUNC('Well calls each plate'!BM5)+6,ROW()+1)) ) )} -> 0.09765625
B6: Aztreonam | C6: {=IF( MOD('Well calls each plate'!C6,1)=0, INDIRECT("'Plate map key'!"&ADDRESS('Well calls each plate'!C6+5,ROW()+1)), AVERAGE( INDIRECT("'Plate map key'!"&ADDRESS(TRUNC('Well calls each plate'!C6)+5,ROW()+1)), INDIRECT("'Plate map key'!"&ADDRESS(TRUNC('Well calls each plate'!C6)+6,ROW()+1)) ) )} -> 0.14648438 | D6: {=IF( MOD('Well calls each plate'!D6,1)=0, INDIRECT("'Plate map key'!"&ADDRESS('Well calls each plate'!D6+5,ROW()+1)), AVERAGE( INDIRECT("'Plate map key'!"&ADDRESS(TRUNC('Well calls each plate'!D6)+5,ROW()+1)), INDIRECT("'Plate map key'!"&ADDRESS(TRUNC('Well calls each plate'!D6)+6,ROW()+1)) ) )} -> 0.09765625 | E6: {=IF( MOD('Well calls each plate'!E6,1)=0, INDIRECT("'Plate map key'!"&ADDRESS('Well calls each plate'!E6+5,ROW()+1)), AVERAGE( INDIRECT("'Plate map key'!"&ADDRESS(TRUNC('Well calls each plate'!E6)+5,ROW()+1)), INDIRECT("'Plate map key'!"&ADDRESS(TRUNC('Well calls each plate'!E6)+6,ROW()+1)) ) )} -> 0.09765625 | F6: {=IF( MOD('Well calls each plate'!F6,1)=0, INDIRECT("'Plate map key'!"&ADDRESS('Well calls each plate'!F6+5,ROW()+1)), AVERAGE( INDIRECT("'Plate map key'!"&ADDRESS(TRUNC('Well calls each plate'!F6)+5,ROW()+1)), INDIRECT("'Plate map key'!"&ADDRESS(TRUNC('Well calls each plate'!F6)+6,ROW()+1)) ) )} -> 0.018310547 | G6: {=IF( MOD('Well calls each plate'!G6,1)=0, INDIRECT("'Plate map key'!"&ADDRESS('Well calls each plate'!G6+5,ROW()+1)), AVERAGE( INDIRECT("'Plate map key'!"&ADDRESS(TRUNC('Well calls each plate'!G6)+5,ROW()+1)), INDIRECT("'Plate map key'!"&ADDRESS(TRUNC('Well calls each plate'!G6)+6,ROW()+1)) ) )} -> 0.018310547 | H6: {=IF( MOD('Well calls each plate'!H6,1)=0, INDIRECT("'Plate map key'!"&ADDRESS('Well calls each plate'!H6+5,ROW()+1)), AVERAGE( INDIRECT("'Plate map key'!"&ADDRESS(TRUNC('Well calls each plate'!H6)+5,ROW()+1)), INDIRECT("'Plate map key'!"&ADDRESS(TRUNC('Well calls each plate'!H6)+6,ROW()+1)) ) )} -> 0.018310547 | I6: {=IF( MOD('Well calls each plate'!I6,1)=0, INDIRECT("'Plate map key'!"&ADDRESS('Well calls each plate'!I6+5,ROW()+1)), AVERAGE( INDIRECT("'Plate map key'!"&ADDRESS(TRUNC('Well calls each plate'!I6)+5,ROW()+1)), INDIRECT("'Plate map key'!"&ADDRESS(TRUNC('Well calls each plate'!I6)+6,ROW()+1)) ) )} -> 0.048828125 | J6: {=IF( MOD('Well calls each plate'!J6,1)=0, INDIRECT("'Plate map key'!"&ADDRESS('Well calls each plate'!J6+5,ROW()+1)), AVERAGE( INDIRECT("'Plate map key'!"&ADDRESS(TRUNC('Well calls each plate'!J6)+5,ROW()+1)), INDIRECT("'Plate map key'!"&ADDRESS(TRUNC('Well calls each plate'!J6)+6,ROW()+1)) ) )} -> 0.048828125 | ... BM6: {=IF( MOD('Well calls each plate'!BM6,1)=0, INDIRECT("'Plate map key'!"&ADDRESS('Well calls each plate'!BM6+5,ROW()+1)), AVERAGE( INDIRECT("'Plate map key'!"&ADDRESS(TRUNC('Well calls each plate'!BM6)+5,ROW()+1)), INDIRECT("'Plate map key'!"&ADDRESS(TRUNC('Well calls each plate'!BM6)+6,ROW()+1)) ) )} -> 0.012207031
B7: Azithromycin | C7: {=IF( MOD('Well calls each plate'!C7,1)=0, INDIRECT("'Plate map key'!"&ADDRESS('Well calls each plate'!C7+5,ROW()+1)), AVERAGE( INDIRECT("'Plate map key'!"&ADDRESS(TRUNC('Well calls each plate'!C7)+5,ROW()+1)), INDIRECT("'Plate map key'!"&ADDRESS(TRUNC('Well calls each plate'!C7)+6,ROW()+1)) ) )} -> 1.4648438 | D7: {=IF( MOD('Well calls each plate'!D7,1)=0, INDIRECT("'Plate map key'!"&ADDRESS('Well calls each plate'!D7+5,ROW()+1)), AVERAGE( INDIRECT("'Plate map key'!"&ADDRESS(TRUNC('Well calls each plate'!D7)+5,ROW()+1)), INDIRECT("'Plate map key'!"&ADDRESS(TRUNC('Well calls each plate'!D7)+6,ROW()+1)) ) )} -> 1.4648438 | E7: {=IF( MOD('Well calls each plate'!E7,1)=0, INDIRECT("'Plate map key'!"&ADDRESS('Well calls each plate'!E7+5,ROW()+1)), AVERAGE( INDIRECT("'Plate map key'!"&ADDRESS(TRUNC('Well calls each plate'!E7)+5,ROW()+1)), INDIRECT("'Plate map key'!"&ADDRESS(TRUNC('Well calls each plate'!E7)+6,ROW()+1)) ) )} -> 0.9765625 | F7: {=IF( MOD('Well calls each plate'!F7,1)=0, INDIRECT("'Plate map key'!"&ADDRESS('Well calls each plate'!F7+5,ROW()+1)), AVERAGE( INDIRECT("'Plate map key'!"&ADDRESS(TRUNC('Well calls each plate'!F7)+5,ROW()+1)), INDIRECT("'Plate map key'!"&ADDRESS(TRUNC('Well calls each plate'!F7)+6,ROW()+1)) ) )} -> 3.90625 | G7: {=IF( MOD('Well calls each plate'!G7,1)=0, INDIRECT("'Plate map key'!"&ADDRESS('Well calls each plate'!G7+5,ROW()+1)), AVERAGE( INDIRECT("'Plate map key'!"&ADDRESS(TRUNC('Well calls each plate'!G7)+5,ROW()+1)), INDIRECT("'Plate map key'!"&ADDRESS(TRUNC('Well calls each plate'!G7)+6,ROW()+1)) ) )} -> 3.90625 | H7: {=IF( MOD('Well calls each plate'!H7,1)=0, INDIRECT("'Plate map key'!"&ADDRESS('Well calls each plate'!H7+5,ROW()+1)), AVERAGE( INDIRECT("'Plate map key'!"&ADDRESS(TRUNC('Well calls each plate'!H7)+5,ROW()+1)), INDIRECT("'Plate map key'!"&ADDRESS(TRUNC('Well calls each plate'!H7)+6,ROW()+1)) ) )} -> 3.90625 | I7: {=IF( MOD('Well calls each plate'!I7,1)=0, INDIRECT("'Plate map key'!"&ADDRESS('Well calls each plate'!I7+5,ROW()+1)), AVERAGE( INDIRECT("'Plate map key'!"&ADDRESS(TRUNC('Well calls each plate'!I7)+5,ROW()+1)), INDIRECT("'Plate map key'!"&ADDRESS(TRUNC('Well calls each plate'!I7)+6,ROW()+1)) ) )} -> 0.12207031 | J7: {=IF( MOD('Well calls each plate'!J7,1)=0, INDIRECT("'Plate map key'!"&ADDRESS('Well calls each plate'!J7+5,ROW()+1)), AVERAGE( INDIRECT("'Plate map key'!"&ADDRESS(TRUNC('Well calls each plate'!J7)+5,ROW()+1)), INDIRECT("'Plate map key'!"&ADDRESS(TRUNC('Well calls each plate'!J7)+6,ROW()+1)) ) )} -> 0.24414062 | ... BM7: {=IF( MOD('Well calls each plate'!BM7,1)=0, INDIRECT("'Plate map key'!"&ADDRESS('Well calls each plate'!BM7+5,ROW()+1)), AVERAGE( INDIRECT("'Plate map key'!"&ADDRESS(TRUNC('Well calls each plate'!BM7)+5,ROW()+1)), INDIRECT("'Plate map key'!"&ADDRESS(TRUNC('Well calls each plate'!BM7)+6,ROW()+1)) ) )} -> 7.8125
B8: Tetracycline HCl | C8: {=IF( MOD('Well calls each plate'!C8,1)=0, INDIRECT("'Plate map key'!"&ADDRESS('Well calls each plate'!C8+5,ROW()+1)), AVERAGE( INDIRECT("'Plate map key'!"&ADDRESS(TRUNC('Well calls each plate'!C8)+5,ROW()+1)), INDIRECT("'Plate map key'!"&ADDRESS(TRUNC('Well calls each plate'!C8)+6,ROW()+1)) ) )} -> 1.5 | D8: {=IF( MOD('Well calls each plate'!D8,1)=0, INDIRECT("'Plate map key'!"&ADDRESS('Well calls each plate'!D8+5,ROW()+1)), AVERAGE( INDIRECT("'Plate map key'!"&ADDRESS(TRUNC('Well calls each plate'!D8)+5,ROW()+1)), INDIRECT("'Plate map key'!"&ADDRESS(TRUNC('Well calls each plate'!D8)+6,ROW()+1)) ) )} -> 1 | E8: {=IF( MOD('Well calls each plate'!E8,1)=0, INDIRECT("'Plate map key'!"&ADDRESS('Well calls each plate'!E8+5,ROW()+1)), AVERAGE( INDIRECT("'Plate map key'!"&ADDRESS(TRUNC('Well calls each plate'!E8)+5,ROW()+1)), INDIRECT("'Plate map key'!"&ADDRESS(TRUNC('Well calls each plate'!E8)+6,ROW()+1)) ) )} -> 1 | F8: {=IF( MOD('Well calls each plate'!F8,1)=0, INDIRECT("'Plate map key'!"&ADDRESS('Well calls each plate'!F8+5,ROW()+1)), AVERAGE( INDIRECT("'Plate map key'!"&ADDRESS(TRUNC('Well calls each plate'!F8)+5,ROW()+1)), INDIRECT("'Plate map key'!"&ADDRESS(TRUNC('Well calls each plate'!F8)+6,ROW()+1)) ) )} -> 0.75 | G8: {=IF( MOD('Well calls each plate'!G8,1)=0, INDIRECT("'Plate map key'!"&ADDRESS('Well calls each plate'!G8+5,ROW()+1)), AVERAGE( INDIRECT("'Plate map key'!"&ADDRESS(TRUNC('Well calls each plate'!G8)+5,ROW()+1)), INDIRECT("'Plate map key'!"&ADDRESS(TRUNC('Well calls each plate'!G8)+6,ROW()+1)) ) )} -> 0.75 | H8: {=IF( MOD('Well calls each plate'!H8,1)=0, INDIRECT("'Plate map key'!"&ADDRESS('Well calls each plate'!H8+5,ROW()+1)), AVERAGE( INDIRECT("'Plate map key'!"&ADDRESS(TRUNC('Well calls each plate'!H8)+5,ROW()+1)), INDIRECT("'Plate map key'!"&ADDRESS(TRUNC('Well calls each plate'!H8)+6,ROW()+1)) ) )} -> 0.75 | I8: {=IF( MOD('Well calls each plate'!I8,1)=0, INDIRECT("'Plate map key'!"&ADDRESS('Well calls each plate'!I8+5,ROW()+1)), AVERAGE( INDIRECT("'Plate map key'!"&ADDRESS(TRUNC('Well calls each plate'!I8)+5,ROW()+1)), INDIRECT("'Plate map key'!"&ADDRESS(TRUNC('Well calls each plate'!I8)+6,ROW()+1)) ) )} -> 8 | J8: {=IF( MOD('Well calls each plate'!J8,1)=0, INDIRECT("'Plate map key'!"&ADDRESS('Well calls each plate'!J8+5,ROW()+1)), AVERAGE( INDIRECT("'Plate map key'!"&ADDRESS(TRUNC('Well calls each plate'!J8)+5,ROW()+1)), INDIRECT("'Plate map key'!"&ADDRESS(TRUNC('Well calls each plate'!J8)+6,ROW()+1)) ) )} -> 8 | ... BM8: {=IF( MOD('Well calls each plate'!BM8,1)=0, INDIRECT("'Plate map key'!"&ADDRESS('Well calls each plate'!BM8+5,ROW()+1)), AVERAGE( INDIRECT("'Plate map key'!"&ADDRESS(TRUNC('Well calls each plate'!BM8)+5,ROW()+1)), INDIRECT("'Plate map key'!"&ADDRESS(TRUNC('Well calls each plate'!BM8)+6,ROW()+1)) ) )} -> 1
B9: Kanamycin | C9: {=IF( MOD('Well calls each plate'!C9,1)=0, INDIRECT("'Plate map key'!"&ADDRESS('Well calls each plate'!C9+5,ROW()+1)), AVERAGE( INDIRECT("'Plate map key'!"&ADDRESS(TRUNC('Well calls each plate'!C9)+5,ROW()+1)), INDIRECT("'Plate map key'!"&ADDRESS(TRUNC('Well calls each plate'!C9)+6,ROW()+1)) ) )} -> 7.8125 | D9: {=IF( MOD('Well calls each plate'!D9,1)=0, INDIRECT("'Plate map key'!"&ADDRESS('Well calls each plate'!D9+5,ROW()+1)), AVERAGE( INDIRECT("'Plate map key'!"&ADDRESS(TRUNC('Well calls each plate'!D9)+5,ROW()+1)), INDIRECT("'Plate map key'!"&ADDRESS(TRUNC('Well calls each plate'!D9)+6,ROW()+1)) ) )} -> 5.859375 | E9: {=IF( MOD('Well calls each plate'!E9,1)=0, INDIRECT("'Plate map key'!"&ADDRESS('Well calls each plate'!E9+5,ROW()+1)), AVERAGE( INDIRECT("'Plate map key'!"&ADDRESS(TRUNC('Well calls each plate'!E9)+5,ROW()+1)), INDIRECT("'Plate map key'!"&ADDRESS(TRUNC('Well calls each plate'!E9)+6,ROW()+1)) ) )} -> 5.859375 | F9: {=IF( MOD('Well calls each plate'!F9,1)=0, INDIRECT("'Plate map key'!"&ADDRESS('Well calls each plate'!F9+5,ROW()+1)), AVERAGE( INDIRECT("'Plate map key'!"&ADDRESS(TRUNC('Well calls each plate'!F9)+5,ROW()+1)), INDIRECT("'Plate map key'!"&ADDRESS(TRUNC('Well calls each plate'!F9)+6,ROW()+1)) ) )} -> 7.8125 | G9: {=IF( MOD('Well calls each plate'!G9,1)=0, INDIRECT("'Plate map key'!"&ADDRESS('Well calls each plate'!G9+5,ROW()+1)), AVERAGE( INDIRECT("'Plate map key'!"&ADDRESS(TRUNC('Well calls each plate'!G9)+5,ROW()+1)), INDIRECT("'Plate map key'!"&ADDRESS(TRUNC('Well calls each plate'!G9)+6,ROW()+1)) ) )} -> 15.625 | H9: {=IF( MOD('Well calls each plate'!H9,1)=0, INDIRECT("'Plate map key'!"&ADDRESS('Well calls each plate'!H9+5,ROW()+1)), AVERAGE( INDIRECT("'Plate map key'!"&ADDRESS(TRUNC('Well calls each plate'!H9)+5,ROW()+1)), INDIRECT("'Plate map key'!"&ADDRESS(TRUNC('Well calls each plate'!H9)+6,ROW()+1)) ) )} -> 15.625 | I9: {=IF( MOD('Well calls each plate'!I9,1)=0, INDIRECT("'Plate map key'!"&ADDRESS('Well calls each plate'!I9+5,ROW()+1)), AVERAGE( INDIRECT("'Plate map key'!"&ADDRESS(TRUNC('Well calls each plate'!I9)+5,ROW()+1)), INDIRECT("'Plate map key'!"&ADDRESS(TRUNC('Well calls each plate'!I9)+6,ROW()+1)) ) )} -> 0.24414062 | J9: {=IF( MOD('Well calls each plate'!J9,1)=0, INDIRECT("'Plate map key'!"&ADDRESS('Well calls each plate'!J9+5,ROW()+1)), AVERAGE( INDIRECT("'Plate map key'!"&ADDRESS(TRUNC('Well calls each plate'!J9)+5,ROW()+1)), INDIRECT("'Plate map key'!"&ADDRESS(TRUNC('Well calls each plate'!J9)+6,ROW()+1)) ) )} -> 7 | ... BM9: {=IF( MOD('Well calls each plate'!BM9,1)=0, INDIRECT("'Plate map key'!"&ADDRESS('Well calls each plate'!BM9+5,ROW()+1)), AVERAGE( INDIRECT("'Plate map key'!"&ADDRESS(TRUNC('Well calls each plate'!BM9)+5,ROW()+1)), INDIRECT("'Plate map key'!"&ADDRESS(TRUNC('Well calls each plate'!BM9)+6,ROW()+1)) ) )} -> 3.90625
B10: Trimethoprim | C10: {=IF( MOD('Well calls each plate'!C10,1)=0, INDIRECT("'Plate map key'!"&ADDRESS('Well calls each plate'!C10+5,ROW()+1)), AVERAGE( INDIRECT("'Plate map key'!"&ADDRESS(TRUNC('Well calls each plate'!C10)+5,ROW()+1)), INDIRECT("'Plate map key'!"&ADDRESS(TRUNC('Well calls each plate'!C10)+6,ROW()+1)) ) )} -> 0.73242188 | D10: {=IF( MOD('Well calls each plate'!D10,1)=0, INDIRECT("'Plate map key'!"&ADDRESS('Well calls each plate'!D10+5,ROW()+1)), AVERAGE( INDIRECT("'Plate map key'!"&ADDRESS(TRUNC('Well calls each plate'!D10)+5,ROW()+1)), INDIRECT("'Plate map key'!"&ADDRESS(TRUNC('Well calls each plate'!D10)+6,ROW()+1)) ) )} -> 0.73242188 | E10: {=IF( MOD('Well calls each plate'!E10,1)=0, INDIRECT("'Plate map key'!"&ADDRESS('Well calls each plate'!E10+5,ROW()+1)), AVERAGE( INDIRECT("'Plate map key'!"&ADDRESS(TRUNC('Well calls each plate'!E10)+5,ROW()+1)), INDIRECT("'Plate map key'!"&ADDRESS(TRUNC('Well calls each plate'!E10)+6,ROW()+1)) ) )} -> 0.73242188 | F10: {=IF( MOD('Well calls each plate'!F10,1)=0, INDIRECT("'Plate map key'!"&ADDRESS('Well calls each plate'!F10+5,ROW()+1)), AVERAGE( INDIRECT("'Plate map key'!"&ADDRESS(TRUNC('Well calls each plate'!F10)+5,ROW()+1)), INDIRECT("'Plate map key'!"&ADDRESS(TRUNC('Well calls each plate'!F10)+6,ROW()+1)) ) )} -> 0.48828125 | G10: {=IF( MOD('Well calls each plate'!G10,1)=0, INDIRECT("'Plate map key'!"&ADDRESS('Well calls each plate'!G10+5,ROW()+1)), AVERAGE( INDIRECT("'Plate map key'!"&ADDRESS(TRUNC('Well calls each plate'!G10)+5,ROW()+1)), INDIRECT("'Plate map key'!"&ADDRESS(TRUNC('Well calls each plate'!G10)+6,ROW()+1)) ) )} -> 0.73242188 | H10: {=IF( MOD('Well calls each plate'!H10,1)=0, INDIRECT("'Plate map key'!"&ADDRESS('Well calls each plate'!H10+5,ROW()+1)), AVERAGE( INDIRECT("'Plate map key'!"&ADDRESS(TRUNC('Well calls each plate'!H10)+5,ROW()+1)), INDIRECT("'Plate map key'!"&ADDRESS(TRUNC('Well calls each plate'!H10)+6,ROW()+1)) ) )} -> 0.73242188 | I10: {=IF( MOD('Well calls each plate'!I10,1)=0, INDIRECT("'Plate map key'!"&ADDRESS('Well calls each plate'!I10+5,ROW()+1)), AVERAGE( INDIRECT("'Plate map key'!"&ADDRESS(TRUNC('Well calls each plate'!I10)+5,ROW()+1)), INDIRECT("'Plate map key'!"&ADDRESS(TRUNC('Well calls each plate'!I10)+6,ROW()+1)) ) )} -> 0.9765625 | J10: {=IF( MOD('Well calls each plate'!J10,1)=0, INDIRECT("'Plate map key'!"&ADDRESS('Well calls each plate'!J10+5,ROW()+1)), AVERAGE( INDIRECT("'Plate map key'!"&ADDRESS(TRUNC('Well calls each plate'!J10)+5,ROW()+1)), INDIRECT("'Plate map key'!"&ADDRESS(TRUNC('Well calls each plate'!J10)+6,ROW()+1)) ) )} -> 0.9765625 | ... BM10: {=IF( MOD('Well calls each plate'!BM10,1)=0, INDIRECT("'Plate map key'!"&ADDRESS('Well calls each plate'!BM10+5,ROW()+1)), AVERAGE( INDIRECT("'Plate map key'!"&ADDRESS(TRUNC('Well calls each plate'!BM10)+5,ROW()+1)), INDIRECT("'Plate map key'!"&ADDRESS(TRUNC('Well calls each plate'!BM10)+6,ROW()+1)) ) )} -> 0.9765625
B11: Sulfamethoxazole | C11: {=IF( MOD('Well calls each plate'!C11,1)=0, INDIRECT("'Plate map key'!"&ADDRESS('Well calls each plate'!C11+5,ROW()+1)), AVERAGE( INDIRECT("'Plate map key'!"&ADDRESS(TRUNC('Well calls each plate'!C11)+5,ROW()+1)), INDIRECT("'Plate map key'!"&ADDRESS(TRUNC('Well calls each plate'!C11)+6,ROW()+1)) ) )} -> 250 | D11: {=IF( MOD('Well calls each plate'!D11,1)=0, INDIRECT("'Plate map key'!"&ADDRESS('Well calls each plate'!D11+5,ROW()+1)), AVERAGE( INDIRECT("'Plate map key'!"&ADDRESS(TRUNC('Well calls each plate'!D11)+5,ROW()+1)), INDIRECT("'Plate map key'!"&ADDRESS(TRUNC('Well calls each plate'!D11)+6,ROW()+1)) ) )} -> 250 | E11: {=IF( MOD('Well calls each plate'!E11,1)=0, INDIRECT("'Plate map key'!"&ADDRESS('Well calls each plate'!E11+5,ROW()+1)), AVERAGE( INDIRECT("'Plate map key'!"&ADDRESS(TRUNC('Well calls each plate'!E11)+5,ROW()+1)), INDIRECT("'Plate map key'!"&ADDRESS(TRUNC('Well calls each plate'!E11)+6,ROW()+1)) ) )} -> 250 | F11: {=IF( MOD('Well calls each plate'!F11,1)=0, INDIRECT("'Plate map key'!"&ADDRESS('Well calls each plate'!F11+5,ROW()+1)), AVERAGE( INDIRECT("'Plate map key'!"&ADDRESS(TRUNC('Well calls each plate'!F11)+5,ROW()+1)), INDIRECT("'Plate map key'!"&ADDRESS(TRUNC('Well calls each plate'!F11)+6,ROW()+1)) ) )} -> 250 | G11: {=IF( MOD('Well calls each plate'!G11,1)=0, INDIRECT("'Plate map key'!"&ADDRESS('Well calls each plate'!G11+5,ROW()+1)), AVERAGE( INDIRECT("'Plate map key'!"&ADDRESS(TRUNC('Well calls each plate'!G11)+5,ROW()+1)), INDIRECT("'Plate map key'!"&ADDRESS(TRUNC('Well calls each plate'!G11)+6,ROW()+1)) ) )} -> 250 | H11: {=IF( MOD('Well calls each plate'!H11,1)=0, INDIRECT("'Plate map key'!"&ADDRESS('Well calls each plate'!H11+5,ROW()+1)), AVERAGE( INDIRECT("'Plate map key'!"&ADDRESS(TRUNC('Well calls each plate'!H11)+5,ROW()+1)), INDIRECT("'Plate map key'!"&ADDRESS(TRUNC('Well calls each plate'!H11)+6,ROW()+1)) ) )} -> 250 | I11: {=IF( MOD('Well calls each plate'!I11,1)=0, INDIRECT("'Plate map key'!"&ADDRESS('Well calls each plate'!I11+5,ROW()+1)), AVERAGE( INDIRECT("'Plate map key'!"&ADDRESS(TRUNC('Well calls each plate'!I11)+5,ROW()+1)), INDIRECT("'Plate map key'!"&ADDRESS(TRUNC('Well calls each plate'!I11)+6,ROW()+1)) ) )} -> 125 | J11: {=IF( MOD('Well calls each plate'!J11,1)=0, INDIRECT("'Plate map key'!"&ADDRESS('Well calls each plate'!J11+5,ROW()+1)), AVERAGE( INDIRECT("'Plate map key'!"&ADDRESS(TRUNC('Well calls each plate'!J11)+5,ROW()+1)), INDIRECT("'Plate map key'!"&ADDRESS(TRUNC('Well calls each plate'!J11)+6,ROW()+1)) ) )} -> 125 | ... Q11: {=IF( MOD('Well calls each plate'!Q11,1)=0, INDIRECT("'Plate map key'!"&ADDRESS('Well calls each plate'!Q11+5,ROW()+1)), AVERAGE( INDIRECT("'Plate map key'!"&ADDRESS(TRUNC('Well calls each plate'!Q11)+5,ROW()+1)), INDIRECT("'Plate map key'!"&ADDRESS(TRUNC('Well calls each plate'!Q11)+6,ROW()+1)) ) )} -> 125 | R11: =MEDIAN(S11:T11) -> 35.15625 | S11: {=IF( MOD('Well calls each plate'!S11,1)=0, INDIRECT("'Plate map key'!"&ADDRESS('Well calls each plate'!S11+5,ROW()+1)), AVERAGE( INDIRECT("'Plate map key'!"&ADDRESS(TRUNC('Well calls each plate'!S11)+5,ROW()+1)), INDIRECT("'Plate map key'!"&ADDRESS(TRUNC('Well calls each plate'!S11)+6,ROW()+1)) ) )} -> 46.875 | T11: {=IF( MOD('Well calls each plate'!T11,1)=0, INDIRECT("'Plate map key'!"&ADDRESS('Well calls each plate'!T11+5,ROW()+1)), AVERAGE( INDIRECT("'Plate map key'!"&ADDRESS(TRUNC('Well calls each plate'!T11)+5,ROW()+1)), INDIRECT("'Plate map key'!"&ADDRESS(TRUNC('Well calls each plate'!T11)+6,ROW()+1)) ) )} -> 23.4375 | U11: {=IF( MOD('Well calls each plate'!U11,1)=0, INDIRECT("'Plate map key'!"&ADDRESS('Well calls each plate'!U11+5,ROW()+1)), AVERAGE( INDIRECT("'Plate map key'!"&ADDRESS(TRUNC('Well calls each plate'!U11)+5,ROW()+1)), INDIRECT("'Plate map key'!"&ADDRESS(TRUNC('Well calls each plate'!U11)+6,ROW()+1)) ) )} -> 23.4375 | V11: {=IF( MOD('Well calls each plate'!V11,1)=0, INDIRECT("'Plate map key'!"&ADDRESS('Well calls each plate'!V11+5,ROW()+1)), AVERAGE( INDIRECT("'Plate map key'!"&ADDRESS(TRUNC('Well calls each plate'!V11)+5,ROW()+1)), INDIRECT("'Plate map key'!"&ADDRESS(TRUNC('Well calls each plate'!V11)+6,ROW()+1)) ) )} -> 23.4375 | W11: {=IF( MOD('Well calls each plate'!W11,1)=0, INDIRECT("'Plate map key'!"&ADDRESS('Well calls each plate'!W11+5,ROW()+1)), AVERAGE( INDIRECT("'Plate map key'!"&ADDRESS(TRUNC('Well calls each plate'!W11)+5,ROW()+1)), INDIRECT("'Plate map key'!"&ADDRESS(TRUNC('Well calls each plate'!W11)+6,ROW()+1)) ) )} -> 23.4375 | X11: {=IF( MOD('Well calls each plate'!X11,1)=0, INDIRECT("'Plate map key'!"&ADDRESS('Well calls each plate'!X11+5,ROW()+1)), AVERAGE( INDIRECT("'Plate map key'!"&ADDRESS(TRUNC('Well calls each plate'!X11)+5,ROW()+1)), INDIRECT("'Plate map key'!"&ADDRESS(TRUNC('Well calls each plate'!X11)+6,ROW()+1)) ) )} -> 23.4375 | Y11: {=IF( MOD('Well calls each plate'!Y11,1)=0, INDIRECT("'Plate map key'!"&ADDRESS('Well calls each plate'!Y11+5,ROW()+1)), AVERAGE( INDIRECT("'Plate map key'!"&ADDRESS(TRUNC('Well calls each plate'!Y11)+5,ROW()+1)), INDIRECT("'Plate map key'!"&ADDRESS(TRUNC('Well calls each plate'!Y11)+6,ROW()+1)) ) )} -> 11.71875 | Z11: {=IF( MOD('Well calls each plate'!Z11,1)=0, INDIRECT("'Plate map key'!"&ADDRESS('Well calls each plate'!Z11+5,ROW()+1)), AVERAGE( INDIRECT("'Plate map key'!"&ADDRESS(TRUNC('Well calls each plate'!Z11)+5,ROW()+1)), INDIRECT("'Plate map key'!"&ADDRESS(TRUNC('Well calls each plate'!Z11)+6,ROW()+1)) ) )} -> 23.4375 | ... BM11: {=IF( MOD('Well calls each plate'!BM11,1)=0, INDIRECT("'Plate map key'!"&ADDRESS('Well calls each plate'!BM11+5,ROW()+1)), AVERAGE( INDIRECT("'Plate map key'!"&ADDRESS(TRUNC('Well calls each plate'!BM11)+5,ROW()+1)), INDIRECT("'Plate map key'!"&ADDRESS(TRUNC('Well calls each plate'!BM11)+6,ROW()+1)) ) )} -> 0.9765625
B12: Colistin | C12: {=IF( MOD('Well calls each plate'!C12,1)=0, INDIRECT("'Plate map key'!"&ADDRESS('Well calls each plate'!C12+5,ROW()+1)), AVERAGE( INDIRECT("'Plate map key'!"&ADDRESS(TRUNC('Well calls each plate'!C12)+5,ROW()+1)), INDIRECT("'Plate map key'!"&ADDRESS(TRUNC('Well calls each plate'!C12)+6,ROW()+1)) ) )} -> 0.78125 | D12: {=IF( MOD('Well calls each plate'!D12,1)=0, INDIRECT("'Plate map key'!"&ADDRESS('Well calls each plate'!D12+5,ROW()+1)), AVERAGE( INDIRECT("'Plate map key'!"&ADDRESS(TRUNC('Well calls each plate'!D12)+5,ROW()+1)), INDIRECT("'Plate map key'!"&ADDRESS(TRUNC('Well calls each plate'!D12)+6,ROW()+1)) ) )} -> 10 | E12: {=IF( MOD('Well calls each plate'!E12,1)=0, INDIRECT("'Plate map key'!"&ADDRESS('Well calls each plate'!E12+5,ROW()+1)), AVERAGE( INDIRECT("'Plate map key'!"&ADDRESS(TRUNC('Well calls each plate'!E12)+5,ROW()+1)), INDIRECT("'Plate map key'!"&ADDRESS(TRUNC('Well calls each plate'!E12)+6,ROW()+1)) ) )} -> 0.78125 | F12: {=IF( MOD('Well calls each plate'!F12,1)=0, INDIRECT("'Plate map key'!"&ADDRESS('Well calls each plate'!F12+5,ROW()+1)), AVERAGE( INDIRECT("'Plate map key'!"&ADDRESS(TRUNC('Well calls each plate'!F12)+5,ROW()+1)), INDIRECT("'Plate map key'!"&ADDRESS(TRUNC('Well calls each plate'!F12)+6,ROW()+1)) ) )} -> 0.78125 | G12: {=IF( MOD('Well calls each plate'!G12,1)=0, INDIRECT("'Plate map key'!"&ADDRESS('Well calls each plate'!G12+5,ROW()+1)), AVERAGE( INDIRECT("'Plate map key'!"&ADDRESS(TRUNC('Well calls each plate'!G12)+5,ROW()+1)), INDIRECT("'Plate map key'!"&ADDRESS(TRUNC('Well calls each plate'!G12)+6,ROW()+1)) ) )} -> 0.78125 | H12: {=IF( MOD('Well calls each plate'!H12,1)=0, INDIRECT("'Plate map key'!"&ADDRESS('Well calls each plate'!H12+5,ROW()+1)), AVERAGE( INDIRECT("'Plate map key'!"&ADDRESS(TRUNC('Well calls each plate'!H12)+5,ROW()+1)), INDIRECT("'Plate map key'!"&ADDRESS(TRUNC('Well calls each plate'!H12)+6,ROW()+1)) ) )} -> 1.5625 | I12: {=IF( MOD('Well calls each plate'!I12,1)=0, INDIRECT("'Plate map key'!"&ADDRESS('Well calls each plate'!I12+5,ROW()+1)), AVERAGE( INDIRECT("'Plate map key'!"&ADDRESS(TRUNC('Well calls each plate'!I12)+5,ROW()+1)), INDIRECT("'Plate map key'!"&ADDRESS(TRUNC('Well calls each plate'!I12)+6,ROW()+1)) ) )} -> 0.78125 | J12: {=IF( MOD('Well calls each plate'!J12,1)=0, INDIRECT("'Plate map key'!"&ADDRESS('Well calls each plate'!J12+5,ROW()+1)), AVERAGE( INDIRECT("'Plate map key'!"&ADDRESS(TRUNC('Well calls each plate'!J12)+5,ROW()+1)), INDIRECT("'Plate map key'!"&ADDRESS(TRUNC('Well calls each plate'!J12)+6,ROW()+1)) ) )} -> 0.78125 | ... BM12: {=IF( MOD('Well calls each plate'!BM12,1)=0, INDIRECT("'Plate map key'!"&ADDRESS('Well calls each plate'!BM12+5,ROW()+1)), AVERAGE( INDIRECT("'Plate map key'!"&ADDRESS(TRUNC('Well calls each plate'!BM12)+5,ROW()+1)), INDIRECT("'Plate map key'!"&ADDRESS(TRUNC('Well calls each plate'!BM12)+6,ROW()+1)) ) )} -> 1.5625
B13: Nitrofurantoin | C13: {=IF( MOD('Well calls each plate'!C13,1)=0, INDIRECT("'Plate map key'!"&ADDRESS('Well calls each plate'!C13+5,ROW()+1)), AVERAGE( INDIRECT("'Plate map key'!"&ADDRESS(TRUNC('Well calls each plate'!C13)+5,ROW()+1)), INDIRECT("'Plate map key'!"&ADDRESS(TRUNC('Well calls each plate'!C13)+6,ROW()+1)) ) )} -> 11.71875 | D13: {=IF( MOD('Well calls each plate'!D13,1)=0, INDIRECT("'Plate map key'!"&ADDRESS('Well calls each plate'!D13+5,ROW()+1)), AVERAGE( INDIRECT("'Plate map key'!"&ADDRESS(TRUNC('Well calls each plate'!D13)+5,ROW()+1)), INDIRECT("'Plate map key'!"&ADDRESS(TRUNC('Well calls each plate'!D13)+6,ROW()+1)) ) )} -> 11.71875 | E13: {=IF( MOD('Well calls each plate'!E13,1)=0, INDIRECT("'Plate map key'!"&ADDRESS('Well calls each plate'!E13+5,ROW()+1)), AVERAGE( INDIRECT("'Plate map key'!"&ADDRESS(TRUNC('Well calls each plate'!E13)+5,ROW()+1)), INDIRECT("'Plate map key'!"&ADDRESS(TRUNC('Well calls each plate'!E13)+6,ROW()+1)) ) )} -> 11.71875 | F13: {=IF( MOD('Well calls each plate'!F13,1)=0, INDIRECT("'Plate map key'!"&ADDRESS('Well calls each plate'!F13+5,ROW()+1)), AVERAGE( INDIRECT("'Plate map key'!"&ADDRESS(TRUNC('Well calls each plate'!F13)+5,ROW()+1)), INDIRECT("'Plate map key'!"&ADDRESS(TRUNC('Well calls each plate'!F13)+6,ROW()+1)) ) )} -> 15.625 | G13: {=IF( MOD('Well calls each plate'!G13,1)=0, INDIRECT("'Plate map key'!"&ADDRESS('Well calls each plate'!G13+5,ROW()+1)), AVERAGE( INDIRECT("'Plate map key'!"&ADDRESS(TRUNC('Well calls each plate'!G13)+5,ROW()+1)), INDIRECT("'Plate map key'!"&ADDRESS(TRUNC('Well calls each plate'!G13)+6,ROW()+1)) ) )} -> 15.625 | H13: {=IF( MOD('Well calls each plate'!H13,1)=0, INDIRECT("'Plate map key'!"&ADDRESS('Well calls each plate'!H13+5,ROW()+1)), AVERAGE( INDIRECT("'Plate map key'!"&ADDRESS(TRUNC('Well calls each plate'!H13)+5,ROW()+1)), INDIRECT("'Plate map key'!"&ADDRESS(TRUNC('Well calls each plate'!H13)+6,ROW()+1)) ) )} -> 15.625 | I13: {=IF( MOD('Well calls each plate'!I13,1)=0, INDIRECT("'Plate map key'!"&ADDRESS('Well calls each plate'!I13+5,ROW()+1)), AVERAGE( INDIRECT("'Plate map key'!"&ADDRESS(TRUNC('Well calls each plate'!I13)+5,ROW()+1)), INDIRECT("'Plate map key'!"&ADDRESS(TRUNC('Well calls each plate'!I13)+6,ROW()+1)) ) )} -> 31.25 | J13: {=IF( MOD('Well calls each plate'!J13,1)=0, INDIRECT("'Plate map key'!"&ADDRESS('Well calls each plate'!J13+5,ROW()+1)), AVERAGE( INDIRECT("'Plate map key'!"&ADDRESS(TRUNC('Well calls each plate'!J13)+5,ROW()+1)), INDIRECT("'Plate map key'!"&ADDRESS(TRUNC('Well calls each plate'!J13)+6,ROW()+1)) ) )} -> 31.25 | ... BM13: {=IF( MOD('Well calls each plate'!BM13,1)=0, INDIRECT("'Plate map key'!"&ADDRESS('Well calls each plate'!BM13+5,ROW()+1)), AVERAGE( INDIRECT("'Plate map key'!"&ADDRESS(TRUNC('Well calls each plate'!BM13)+5,ROW()+1)), INDIRECT("'Plate map key'!"&ADDRESS(TRUNC('Well calls each plate'!BM13)+6,ROW()+1)) ) )} -> 7.8125
B17: MGCs calculated by using the calls of full or reduced growth in 'Well calls each plate' to select concentration from 'Plate map key.'

Sheet Well calls each plate
B1: Media | C1: BHI | F1: MAGVN | I1: RPMI | L1: LB | O1: DMEM | R1: MAP | U1: MAGV | X1: MHB-F | AA1: MHB-S | AD1: AU | AG1: MHB | AJ1: MAG | AM1: MAFr | AP1: MAR | AS1: MAGly | AV1: MAG-Na | AY1: MAG-Tr | BB1: MAFu | BE1: MA | BH1: MAGN | BK1: MG
B2: Replicate | C2: 1 | D2: 2 | E2: 3 | F2: 1 | G2: 2 | H2: 3 | I2: 1 | J2: 2 | K2: 3 | L2: 1 | M2: 2 | N2: 3 | O2: 1 | P2: 2 | Q2: 3 | R2: 1 | S2: 2 | T2: 3 | U2: 1 | V2: 2 | W2: 3 | X2: 1 | Y2: 2 | Z2: 3 | AA2: 1 | AB2: 2 | AC2: 3 | AD2: 1 | AE2: 2 | AF2: 3 | AG2: 1 | AH2: 2 | AI2: 3 | AJ2: 1 | AK2: 2 | AL2: 3 | AM2: 1 | AN2: 2 | AO2: 3 | AP2: 1 | AQ2: 2 | AR2: 3 | AS2: 1 | AT2: 2 | AU2: 3 | AV2: 1 | AW2: 2 | AX2: 3 | AY2: 1 | AZ2: 2 | BA2: 3 | BB2: 1 | BC2: 2 | BD2: 3 | BE2: 1 | BF2: 2 | BG2: 3 | BH2: 1 | BI2: 2 | BJ2: 3 | BK2: 1 | BL2: 2 | BM2: 3
B3: Ciprofloxacin | C3: 5.5 | D3: 5.5 | E3: 5.5 | F3: 5.5 | G3: 6 | H3: 6.5 | I3: 7 | J3: 7 | K3: 7 | L3: 4.5 | M3: 4.5 | N3: 4.5 | O3: 5 | P3: 5 | Q3: 5 | R3: 6 | S3: 6 | T3: 6 | U3: 6 | V3: 5.5 | W3: 5.5 | X3: 6.5 | Y3: 6.5 | Z3: 6.5 | AA3: 7.5 | AB3: 7.5 | AC3: 7 | AD3: 6 | AE3: 7 | AF3: 7 | AG3: 6 | AH3: 6 | AI3: 6 | AJ3: 5.5 | AK3: 5.5 | AL3: 5.5 | AM3: 5.5 | AN3: 5.5 | AO3: 6 | AP3: 6.5 | AQ3: 6.5 | AR3: 6.5 | AS3: 5.5 | AT3: 5.5 | AU3: 5.5 | AV3: 7 | AW3: 7 | AX3: 6.5 | AY3: 5.5 | AZ3: 5.5 | BA3: 5.5 | BB3: 6.5 | BC3: 6.5 | BD3: 6.5 | BE3: 7.5 | BF3: 7.5 | BG3: 7.5 | BH3: 6 | BI3: 6 | BJ3: 6 | BK3: 7 | BL3: 6.5 | BM3: 6.5
B4: Norfloxacin | C4: 4 | D4: 4 | E4: 4 | F4: 5.5 | G4: 5 | H4: 5.5 | I4: 6 | J4: 7 | K4: 6 | L4: 3.5 | M4: 3.5 | N4: 3.5 | O4: 4 | P4: 4 | Q4: 4 | R4: 5 | S4: 5 | T4: 5 | U4: 5 | V4: 5 | W4: 5 | X4: 5.5 | Y4: 6 | Z4: 6 | AA4: 6.5 | AB4: 6.5 | AC4: 6.5 | AD4: 6 | AE4: 6 | AF4: 6 | AG4: 5.5 | AH4: 5.5 | AI4: 5 | AJ4: 5 | AK4: 5 | AL4: 5 | AM4: 5 | AN4: 5 | AO4: 5 | AP4: 5.5 | AQ4: 6 | AR4: 5.5 | AS4: 5.5 | AT4: 5.5 | AU4: 5.5 | AV4: 6 | AW4: 6 | AX4: 6 | AY4: 5 | AZ4: 5 | BA4: 5 | BB4: 5.5 | BC4: 5.5 | BD4: 5.5 | BE4: 6.5 | BF4: 6.5 | BG4: 6 | BH4: 5 | BI4: 5 | BJ4: 5 | BK4: 6 | BL4: 6 | BM4: 6
B5: Cefdinir | C5: 5 | D5: 5 | E5: 5 | F5: 6.5 | G5: 6 | H5: 6 | I5: 6 | J5: 6 | K5: 6 | L5: 5.5 | M5: 4.5 | N5: 4.5 | O5: 5 | P5: 5 | Q5: 5 | R5: 6 | S5: 7 | T5: 6.5 | U5: 6.5 | V5: 6.5 | W5: 6.5 | X5: 6 | Y5: 5.5 | Z5: 6 | AA5: 5 | AB5: 5.5 | AC5: 5.5 | AD5: 8 | AE5: 8 | AF5: 8 | AG5: 5 | AH5: 5 | AI5: 5 | AJ5: 6.5 | AK5: 6.5 | AL5: 7 | AM5: 6.5 | AN5: 6.5 | AO5: 7 | AP5: 7.5 | AQ5: 7.5 | AR5: 7.5 | AS5: 7.5 | AT5: 7.5 | AU5: 8 | AV5: =MEDIAN(AW5:AX5) -> 5.75 | AW5: 5.5 | AX5: 6 | AY5: 6 | AZ5: 6 | BA5: 6 | BB5: 7.5 | BC5: 7.5 | BD5: 8 | BE5: 8 | BF5: 8 | BG5: 7.5 | BH5: 6.5 | BI5: 7 | BJ5: 6 | BK5: 7.5 | BL5: 7 | BM5: 7
B6: Aztreonam | C6: 3.5 | D6: 4 | E6: 4 | F6: 6.5 | G6: 6.5 | H6: 6.5 | I6: 5 | J6: 5 | K6: 5 | L6: 4.5 | M6: 4.5 | N6: 4.5 | O6: NaN | P6: NaN | Q6: NaN | R6: 7 | S6: 6 | T6: 7 | U6: 5.5 | V6: 5.5 | W6: 5.5 | X6: 4.5 | Y6: 4.5 | Z6: 4.5 | AA6: 4.5 | AB6: 4.5 | AC6: 4.5 | AD6: 8 | AE6: 8 | AF6: 8 | AG6: 3.5 | AH6: 4 | AI6: 4 | AJ6: 5.5 | AK6: 5.5 | AL6: 5.5 | AM6: 6.5 | AN6: 6.5 | AO6: 6.5 | AP6: 7.5 | AQ6: 7.5 | AR6: 7.5 | AS6: 7.5 | AT6: 7.5 | AU6: 7.5 | AV6: 5.5 | AW6: 5.5 | AX6: 5.5 | AY6: 5 | AZ6: 5 | BA6: 5 | BB6: 7.5 | BC6: 7.5 | BD6: 7.5 | BE6: 7.5 | BF6: 7 | BG6: 7.5 | BH6: 6.5 | BI6: 6.5 | BJ6: 6 | BK6: 7 | BL6: 7 | BM6: 7
B7: Azithromycin | C7: 4.5 | D7: 4.5 | E7: 5 | F7: 3 | G7: 3 | H7: 3 | I7: 8 | J7: 7 | K7: 7 | L7: 1 | M7: 1 | N7: 1 | O7: 7 | P7: 7 | Q7: 7 | R7: 3 | S7: 3 | T7: 3 | U7: 3 | V7: 3 | W7: 3 | X7: 5 | Y7: 5.5 | Z7: 5.5 | AA7: 7 | AB7: 7.5 | AC7: 7 | AD7: 5 | AE7: 5 | AF7: 5 | AG7: 4.5 | AH7: 5.5 | AI7: 4.5 | AJ7: 3 | AK7: 3 | AL7: 3 | AM7: 3 | AN7: 3 | AO7: 3 | AP7: 3 | AQ7: 3 | AR7: 3 | AS7: 4 | AT7: 4 | AU7: 3.5 | AV7: 7 | AW7: 7 | AX7: 7 | AY7: 3 | AZ7: 3 | BA7: 3 | BB7: 3.5 | BC7: 3.5 | BD7: 3.5 | BE7: 4 | BF7: 4 | BG7: 4 | BH7: 3 | BI7: 3 | BJ7: 3 | BK7: 2 | BL7: 2 | BM7: 2
B8: Tetracycline HCl | C8: 6.5 | D8: 7 | E8: 7 | F8: 7.5 | G8: 7.5 | H8: 7.5 | I8: 4 | J8: 4 | K8: 4 | L8: 5.5 | M8: 6.5 | N8: 6.5 | O8: 1 | P8: 1 | Q8: 1 | R8: 7.5 | S8: 7.5 | T8: 7.5 | U8: 6.5 | V8: 6 | W8: 6 | X8: 6 | Y8: 6 | Z8: 6 | AA8: 7.5 | AB8: 7.5 | AC8: 7.5 | AD8: 6 | AE8: 6 | AF8: 6 | AG8: 6.5 | AH8: 6 | AI8: 6.5 | AJ8: 6.5 | AK8: 6 | AL8: 6 | AM8: 6.5 | AN8: 6.5 | AO8: 6.5 | AP8: 8 | AQ8: 8 | AR8: 8.5 | AS8: 6.5 | AT8: 7 | AU8: 7 | AV8: 6 | AW8: 6 | AX8: 6 | AY8: 6 | AZ8: 6 | BA8: 6 | BB8: 7 | BC8: 7 | BD8: 7 | BE8: 8.5 | BF8: 8.5 | BG8: 8.5 | BH8: 7 | BI8: 7 | BJ8: 7 | BK8: 6.5 | BL8: 7 | BM8: 7
B9: Kanamycin | C9: 4 | D9: 4.5 | E9: 4.5 | F9: 4 | G9: 3 | H9: 3 | I9: 9 | K9: 9 | L9: 3.5 | M9: 4 | N9: 4.5 | O9: 6 | P9: 6 | Q9: 6 | R9: 3.5 | S9: 3 | T9: 3 | U9: 4 | V9: 4 | W9: 4 | X9: 7 | Y9: 7 | Z9: 7 | AA9: 7 | AB9: 6 | AC9: 6 | AD9: 7 | AE9: 7 | AF9: 8 | AG9: 7 | AH9: 7.5 | AI9: 7 | AJ9: 3 | AK9: 4 | AL9: 4 | AM9: 4.5 | AN9: 4 | AO9: 4.5 | AP9: 4.5 | AQ9: 3.5 | AR9: 4 | AS9: 4.5 | AT9: 4 | AU9: 4.5 | AV9: 6 | AW9: 6.5 | AX9: 6 | AY9: 4 | AZ9: 4 | BA9: 4 | BB9: 4.5 | BC9: 4.5 | BD9: 4.5 | BE9: 4.5 | BF9: 4.5 | BG9: 4.5 | BH9: 2 | BI9: 3 | BJ9: 3 | BK9: 6 | BL9: 6 | BM9: 5
B10: Trimethoprim | C10: 5.5 | D10: 5.5 | E10: 5.5 | F10: 6 | G10: 5.5 | H10: 5.5 | I10: 5 | J10: 5 | K10: 5 | L10: 5.5 | M10: 5.5 | N10: 5.5 | O10: 4 | P10: 4 | Q10: 4 | R10: 4.5 | S10: 4 | T10: 4.5 | U10: 4 | V10: 4 | W10: 4 | X10: 6.5 | Y10: 6.5 | Z10: 6.5 | AA10: 7.5 | AB10: 8 | AC10: 8 | AD10: 5 | AE10: 5 | AF10: 5 | AG10: 6 | AH10: 6 | AI10: 5.5 | AJ10: 4 | AK10: 4 | AL10: 4 | AM10: 3.5 | AN10: 3.5 | AO10: 3.5 | AP10: 5.5 | AQ10: 5.5 | AR10: 5.5 | AS10: 4.5 | AT10: 4.5 | AU10: 4.5 | AV10: 4 | AW10: 4.5 | AX10: 4.5 | AY10: 4.5 | AZ10: 4 | BA10: 4.5 | BB10: 6 | BC10: 4.5 | BD10: 4.5 | BE10: 5.5 | BF10: 5.5 | BG10: 5.5 | BH10: 6.5 | BI10: 6 | BJ10: 6 | BK10: 5 | BL10: 5 | BM10: 5
B11: Sulfamethoxazole | C11: 1 | D11: 1 | E11: 1 | F11: 1 | G11: 1 | H11: 1 | I11: 2 | J11: 2 | K11: 2 | L11: 1.5 | M11: 2.5 | N11: 2.5 | O11: 2 | P11: 2 | Q11: 2 | R11: =MEDIAN(S11:T11) -> 4 | S11: 3.5 | T11: 4.5 | U11: 4.5 | V11: 4.5 | W11: 4.5 | X11: 4.5 | Y11: 5.5 | Z11: 4.5 | AA11: 5 | AB11: 4.5 | AC11: 4.5 | AD11: 4 | AE11: 5 | AF11: 5 | AG11: 5.5 | AH11: 5.5 | AI11: 5.5 | AJ11: 5.5 | AK11: 6.5 | AL11: 6.5 | AM11: 6.5 | AN11: 6.5 | AO11: 6.5 | AP11: 6.5 | AQ11: 6.5 | AR11: 6.5 | AS11: 6.5 | AT11: 6.5 | AU11: 6.5 | AV11: 7 | AW11: 7 | AX11: 6.5 | AY11: 7 | AZ11: 7 | BA11: 7.5 | BB11: 7 | BC11: 6.5 | BD11: 7 | BE11: 7.5 | BF11: 7.5 | BG11: 8.5 | BH11: 8 | BI11: 8 | BJ11: 8 | BK11: 9 | BL11: 9 | BM11: 9
B12: Colistin | C12: 5 | E12: 5 | F12: 5 | G12: 5 | H12: 4 | I12: 5 | J12: 5 | K12: 5 | L12: 6 | M12: 6 | N12: 6 | O12: 5 | P12: 5 | Q12: 4 | R12: 4 | S12: 5 | T12: 4 | U12: 5 | V12: 5 | W12: 5 | X12: 5 | Y12: 4 | Z12: 4 | AA12: 4 | AB12: 4 | AC12: 4 | AD12: 5 | AE12: 5 | AF12: 5 | AG12: 4 | AH12: 4 | AI12: 4 | AJ12: 5 | AK12: 5 | AL12: 5 | AM12: 5 | AN12: 5 | AO12: 4 | AP12: 4 | AQ12: 5 | AR12: 4 | AS12: 5 | AT12: 5 | AU12: 4 | AV12: 4 | AW12: 4 | AX12: 4 | AY12: 5 | AZ12: 5 | BA12: 4 | BB12: 5 | BC12: 5 | BD12: 5 | BE12: 5 | BF12: 5 | BG12: 4.5 | BH12: 5 | BI12: 5 | BJ12: 5 | BK12: 4 | BL12: 4 | BM12: 4
B13: Nitrofurantoin | C13: 5.5 | D13: 5.5 | E13: 5.5 | F13: 5 | G13: 5 | H13: 5 | I13: 4 | J13: 4 | K13: 4 | L13: 5.5 | M13: 5.5 | N13: 5.5 | O13: 4 | P13: 4 | Q13: 4 | R13: 5 | S13: 5 | T13: 5 | U13: 5 | V13: 5 | W13: 5 | X13: 4.5 | Y13: 5 | Z13: 5 | AA13: 5 | AB13: 5 | AC13: 5 | AD13: 5 | AE13: 5 | AF13: 5 | AG13: 5 | AH13: 5 | AI13: 4 | AJ13: 4 | AK13: 5 | AL13: 5 | AM13: 4 | AN13: 4.5 | AO13: 4 | AP13: 6 | AQ13: 5 | AR13: 5 | AS13: 5 | AT13: 5 | AU13: 5 | AV13: 3 | AW13: 3 | AX13: 3 | AY13: 5 | AZ13: 5 | BA13: 5 | BB13: 6 | BC13: 6 | BD13: 6 | BE13: 6.5 | BF13: 6.5 | BG13: 6.5 | BH13: 5 | BI13: 5 | BJ13: 5 | BK13: 6 | BL13: 6 | BM13: 6
B17: Values represent which row of the plate was last called to contain 'full growth' using neural network pipeline with manual adjustments as needed. See representation of these values in PowerPoint MGCRecordPlates.pptx.
B18: A value with .5 added indicates the call should be made between rows. For example, a call of 4.5 represents an MGC being averaged between row 4 and row 5 of the drug concentration plate.

Sheet Plate map key
